2024-03-03 11:47:05,839 : INFO : Start of Training
2024-03-03 11:47:05,839 : INFO : Run_id:<bound method Config.run_id of <apps.core.config.Config object at 0x7f1d4559fa90>>
2024-03-03 11:47:05,840 : INFO : Start of reading dataset...
2024-03-03 11:47:11,262 : INFO : End of reading dataset...
2024-03-03 11:47:11,262 : INFO : Start of splitting features and label ...
2024-03-03 11:47:11,264 : INFO : End of splitting features and label ...
2024-03-03 11:47:11,264 : INFO : Saving to database
2024-03-03 11:47:28,642 : INFO : Start of creating table...
2024-03-03 11:47:29,686 : ERROR : Error while connecting to database: 'DatabaseOperation' object has no attribute 'database'
Traceback (most recent call last):
  File "/home/luka/PycharmProjects/UsedCarsML_v1/pythonProject/apps/db/config.py", line 30, in database_connection
    database=self.database,
AttributeError: 'DatabaseOperation' object has no attribute 'database'
2024-03-03 11:47:33,490 : ERROR : Exception raised while creating table: 
Traceback (most recent call last):
  File "/home/luka/PycharmProjects/UsedCarsML_v1/pythonProject/apps/db/config.py", line 30, in database_connection
    database=self.database,
AttributeError: 'DatabaseOperation' object has no attribute 'database'

During handling of the above exception, another exception occurred:

Traceback (most recent call last):
  File "/home/luka/PycharmProjects/UsedCarsML_v1/pythonProject/apps/db/config.py", line 45, in create_table
    conn = self.database_connection(database_name)
  File "/home/luka/PycharmProjects/UsedCarsML_v1/pythonProject/apps/db/config.py", line 39, in database_connection
    raise ConnectionError
ConnectionError
2024-03-03 11:47:33,492 : ERROR : Unsuccessful End of Training
Traceback (most recent call last):
  File "/home/luka/PycharmProjects/UsedCarsML_v1/pythonProject/apps/db/config.py", line 30, in database_connection
    database=self.database,
AttributeError: 'DatabaseOperation' object has no attribute 'database'

During handling of the above exception, another exception occurred:

Traceback (most recent call last):
  File "/home/luka/PycharmProjects/UsedCarsML_v1/pythonProject/apps/training/train.py", line 54, in training_model
    pg_db.create_table(self.training_db, "uc_training_data")
  File "/home/luka/PycharmProjects/UsedCarsML_v1/pythonProject/apps/db/config.py", line 73, in create_table
    raise e
  File "/home/luka/PycharmProjects/UsedCarsML_v1/pythonProject/apps/db/config.py", line 45, in create_table
    conn = self.database_connection(database_name)
  File "/home/luka/PycharmProjects/UsedCarsML_v1/pythonProject/apps/db/config.py", line 39, in database_connection
    raise ConnectionError
ConnectionError
